Workbook

Sheet Info
A3: Module | B3: Admin | C3: User | D3: Moderator | E3: Guest | F3: Adopter Admin | G3: Tenant Admin | H3: Automation | I3: Backend | J3: Sanity
A4: Home | B4: =COUNTIF('Home Page'!E:E,"Yes")+COUNTIF('Home Page'!E:E,"No") -> 1 | C4: =COUNTIF('Home Page'!F:F,"Yes")+COUNTIF('Home Page'!F:F,"No") -> 35 | D4: =COUNTIF('Home Page'!G:G,"Yes")+COUNTIF('Home Page'!G:G,"No") -> 1 | E4: =COUNTIF('Home Page'!H:H,"Yes")+COUNTIF('Home Page'!H:H,"No") -> 1 | F4: =COUNTIF('Home Page'!I:I,"Yes")+COUNTIF('Home Page'!I:I,"No") -> 1 | G4: =COUNTIF('Home Page'!J:J,"Yes")+COUNTIF('Home Page'!J:J,"No") -> 1 | H4: =COUNTIF('Home Page'!K:K,"Yes")+COUNTIF('Home Page'!K:K,"No") -> 0 | I4: =COUNTIF('Home Page'!L:L,"Yes")+COUNTIF('Home Page'!L:L,"No") -> 0 | J4: =COUNTIF('Home Page'!N:N,"Yes")+COUNTIF('Home Page'!N:N,"No") -> 0
A5: Auth | B5: =COUNTIF(Auth!E:E,"Yes")+COUNTIF(Auth!E:E,"No") -> 14 | C5: =COUNTIF(Auth!F:F,"Yes")+COUNTIF(Auth!F:F,"No") -> 13 | D5: =COUNTIF(Auth!G:G,"Yes")+COUNTIF(Auth!G:G,"No") -> 13 | E5: =COUNTIF(Auth!H:H,"Yes")+COUNTIF(Auth!H:H,"No") -> 13 | F5: =COUNTIF(Auth!I:I,"Yes")+COUNTIF(Auth!I:I,"No") -> 0 | G5: =COUNTIF(Auth!J:J,"Yes")+COUNTIF(Auth!J:J,"No") -> 0 | H5: =COUNTIF(Auth!K:K,"Yes")+COUNTIF(Auth!K:K,"No") -> 0 | I5: =COUNTIF(Auth!L:L,"Yes")+COUNTIF(Auth!L:L,"No") -> 0 | J5: =COUNTIF(Auth!M:M,"Sanity") -> 7
A6: User Management | B6: =COUNTIF('User Management'!E:E,"Yes")+COUNTIF('User Management'!E:E,"No") -> 1 | C6: =COUNTIF('User Management'!F:F,"Yes")+COUNTIF('User Management'!F:F,"No") -> 15 | D6: =COUNTIF('User Management'!G:G,"Yes")+COUNTIF('User Management'!G:G,"No") -> 1 | E6: =COUNTIF('User Management'!H:H,"Yes")+COUNTIF('User Management'!H:H,"No") -> 1 | F6: =COUNTIF('User Management'!I:I,"Yes")+COUNTIF('User Management'!I:I,"No") -> 0 | G6: =COUNTIF('User Management'!J:J,"Yes")+COUNTIF('User Management'!J:J,"No") -> 0 | H6: =COUNTIF('User Management'!K:K,"Yes")+COUNTIF('User Management'!K:K,"No") -> 0 | I6: =COUNTIF('User Management'!L:L,"Yes")+COUNTIF('User Management'!L:L,"No") -> 0 | J6: =COUNTIF('User Management'!M:M,"Sanity") -> 3
A7: Role Management | B7: =COUNTIF('Role Management'!E:E,"Yes")+COUNTIF('Role Management'!E:E,"No") -> 15 | C7: =COUNTIF('Role Management'!F:F,"Yes")+COUNTIF('Role Management'!F:F,"No") -> 2 | D7: =COUNTIF('Role Management'!G:G,"Yes")+COUNTIF('Role Management'!G:G,"No") -> 2 | E7: =COUNTIF('Role Management'!H:H,"Yes")+COUNTIF('Role Management'!H:H,"No") -> 2 | F7: =COUNTIF('Role Management'!I:I,"Yes")+COUNTIF('Role Management'!I:I,"No") -> 0 | G7: =COUNTIF('Role Management'!J:J,"Yes")+COUNTIF('Role Management'!J:J,"No") -> 0 | H7: =COUNTIF('Role Management'!K:K,"Yes")+COUNTIF('Role Management'!K:K,"No") -> 0 | I7: =COUNTIF('Role Management'!L:L,"Yes")+COUNTIF('Role Management'!L:L,"No") -> 0 | J7: =COUNTIF('Role Management'!M:M,"Sanity") -> 2
A8: API KEY Management | B8: =COUNTIF('API KEY Management'!E:E,"Yes")+COUNTIF('API KEY Management'!E:E,"No") -> 33 | C8: =COUNTIF('API KEY Management'!F:F,"Yes")+COUNTIF('API KEY Management'!F:F,"No") -> 10 | D8: =COUNTIF('API KEY Management'!G:G,"Yes")+COUNTIF('API KEY Management'!G:G,"No") -> 11 | E8: =COUNTIF('API KEY Management'!H:H,"Yes")+COUNTIF('API KEY Management'!H:H,"No") -> 11 | F8: =COUNTIF('API KEY Management'!I:I,"Yes")+COUNTIF('API KEY Management'!I:I,"No") -> 0 | G8: =COUNTIF('API KEY Management'!J:J,"Yes")+COUNTIF('API KEY Management'!J:J,"No") -> 0 | H8: =COUNTIF('API KEY Management'!K:K,"Yes")+COUNTIF('API KEY Management'!K:K,"No") -> 0 | I8: =COUNTIF('API KEY Management'!L:L,"Yes")+COUNTIF('API KEY Management'!L:L,"No") -> 0 | J8: =COUNTIF('API KEY Management'!M:M,"Sanity") -> 9
A9: Model and Service Management | B9: =COUNTIF('Model and Service Management'!E:E,"Yes")+COUNTIF('Model and Service Management'!E:E,"No") -> 184 | C9: =COUNTIF('Model and Service Management'!F:F,"Yes")+COUNTIF('Model and Service Management'!F:F,"No") -> 2 | D9: =COUNTIF('Model and Service Management'!G:G,"Yes")+COUNTIF('Model and Service Management'!G:G,"No") -> 184 | E9: =COUNTIF('Model and Service Management'!H:H,"Yes")+COUNTIF('Model and Service Management'!H:H,"No") -> 2 | F9: =COUNTIF('Model and Service Management'!I:I,"Yes")+COUNTIF('Model and Service Management'!I:I,"No") -> 0 | G9: =COUNTIF('Model and Service Management'!J:J,"Yes")+COUNTIF('Model and Service Management'!J:J,"No") -> 0 | H9: =COUNTIF('Model and Service Management'!K:K,"Yes")+COUNTIF('Model and Service Management'!K:K,"No") -> 0 | I9: =COUNTIF('Model and Service Management'!L:L,"Yes")+COUNTIF('Model and Service Management'!L:L,"No") -> 0 | J9: =COUNTIF('Model and Service Management'!M:M,"Sanity") -> 21
A10: Services | B10: =COUNTIF(Services!E:E,"Yes")+COUNTIF(Services!E:E,"No") -> 34 | C10: =COUNTIF(Services!F:F,"Yes")+COUNTIF(Services!F:F,"No") -> 271 | D10: =COUNTIF(Services!G:G,"Yes")+COUNTIF(Services!G:G,"No") -> 34 | E10: =COUNTIF(Services!H:H,"Yes")+COUNTIF(Services!H:H,"No") -> 34 | F10: =COUNTIF(Services!I:I,"Yes")+COUNTIF(Services!I:I,"No") -> 34 | G10: =COUNTIF(Services!J:J,"Yes")+COUNTIF(Services!J:J,"No") -> 34 | H10: =COUNTIF(Services!K:K,"Yes")+COUNTIF(Services!K:K,"No") -> 0 | I10: =COUNTIF(Services!L:L,"Yes")+COUNTIF(Services!L:L,"No") -> 0 | J10: =COUNTIF(Services!M:M,"Sanity") -> 47
A11: Multi Tenancy | B11: =COUNTIF('Multi Tenancy'!E:E,"Yes") -> 0 | C11: =COUNTIF('Multi Tenancy'!F:F,"Yes") -> 16 | D11: =COUNTIF('Multi Tenancy'!G:G,"Yes") -> 0 | E11: =COUNTIF('Multi Tenancy'!H:H,"Yes") -> 0 | F11: =COUNTIF('Multi Tenancy'!I:I,"Yes") -> 134 | G11: =COUNTIF('Multi Tenancy'!J:J,"Yes") -> 56 | H11: =COUNTIF('Multi Tenancy'!K:K,"Yes") -> 0 | I11: =COUNTIF('Multi Tenancy'!L:L,"Yes") -> 0
A12: Telemetry | B12: =COUNTIF(Telemetry!E:E,"Yes")+COUNTIF(Telemetry!E:E,"No") -> 97 | C12: =COUNTIF(Telemetry!F:F,"Yes") -> 0 | D12: =COUNTIF(Telemetry!G:G,"Yes") -> 97 | E12: =COUNTIF(Telemetry!H:H,"Yes") -> 0 | F12: =COUNTIF(Telemetry!I:I,"Yes") -> 0 | G12: =COUNTIF(Telemetry!J:J,"Yes") -> 0 | H12: =COUNTIF(Telemetry!K:K,"Yes") -> 0 | I12: =COUNTIF(Telemetry!L:L,"Yes") -> 0
A13: Alerting | B13: =COUNTIF(Alerting!E:E,"Yes")+COUNTIF(Alerting!E:E,"No") -> 12 | C13: =COUNTIF(Alerting!F:F,"Yes")+COUNTIF(Alerting!F:F,"No") -> 12 | D13: =COUNTIF(Alerting!G:G,"Yes")+COUNTIF(Alerting!G:G,"No") -> 12 | E13: =COUNTIF(Alerting!H:H,"Yes")+COUNTIF(Alerting!H:H,"No") -> 12 | F13: =COUNTIF(Alerting!I:I,"Yes")+COUNTIF(Alerting!I:I,"No") -> 111 | G13: =COUNTIF(Alerting!J:J,"Yes")+COUNTIF(Alerting!J:J,"No") -> 12 | H13: =COUNTIF(Alerting!K:K,"Yes")+COUNTIF(Alerting!K:K,"No") -> 0 | I13: =COUNTIF(Alerting!L:L,"Yes")+COUNTIF(Alerting!L:L,"No") -> 0 | J13: =COUNTIF(Alerting!M:M,"Yes")+COUNTIF(Alerting!M:M,"Sanity") -> 17
A14: Alerting Data Validation | B14: =COUNTIF('Alerting Data Validation'!Q:Q,"Yes") -> 22 | J14: =COUNTIF('Alerting Data Validation'!S:S,"Sanity") -> 22
A15: TOTAL | B15: =sum(B4:B13) -> 391 | C15: =sum(C4:C13) -> 376 | D15: =sum(D4:D13) -> 355 | E15: =SUM(E4:E13) -> 76 | F15: =(sum(F4:F13)) -> 280 | G15: =sum(G4:G13) -> 103 | J15: =SUM(J4:J14) -> 128
E17: Grand Total | F17: =(sum(B15:G15)) -> 1581

Sheet Home Page
A1: TC_ID | B1: Module | C1: Description | D1: Functionality | E1: Admin | F1: User | G1: Moderator | H1: Guest | I1: Adopter Admin | J1: Tenanat Admin | K1: UI Automation | L1: Backend | M1: Tags | N1: Created/Update on | O1: Ticket ID
A2: TC_Home_01 | B2: Home | C2: Pre login | D2: Verify that when a user who is not logged in accesses https://staging.ai4inclusion.org, they are able to land on the home page | E2: NA | F2: Yes | G2: NA | H2: NA | I2: NA | J2: NA
A3: TC_Home_02 | B3: Home | C3: Pre login | D3: Verify that a user who is not logged in is restricted from accessing services on https://sandbox.ai4inclusion.org, with the exception of the NMT service | E3: NA | F3: Yes | G3: NA | H3: NA | I3: NA | J3: NA
A4: TC_Home_03 | B4: Home | C4: Pre login | D4: Verify that a user who is not logged in can access the NMT service on https://sandbox.ai4inclusion.org up to a maximum of 5 times as an anonymous user, and is restricted from accessing it beyond that limit | E4: NA | F4: Yes | G4: NA | H4: NA | I4: NA | J4: NA
A5: TC_Home_04 | B5: Home | C5: Pre login | D5: Verify that after a user who is not logged in exceeds 5 attempts on the NMT service, an appropriate error message is displayed: "Access denied. Please login to access this service." | E5: NA | F5: Yes | G5: NA | H5: NA | I5: NA | J5: NA
A6: TC_Home_05 | B6: Home | C6: Pre login | D6: Verify that clicking on 'Home' navigates the user to the Home page | E6: NA | F6: Yes | G6: NA | H6: NA | I6: NA | J6: NA
A7: TC_Home_06 | B7: Home | C7: Pre login | D7: Verify that when a user who is not logged in clicks on any other navigation option (e.g. Services from the side menu, Model Management), they are redirected to the Login page | E7: NA | F7: Yes | G7: NA | H7: NA | I7: NA | J7: NA
A8: TC_Home_07 | B8: Home | C8: Pre login | D8: Verify that when a user who is not logged in clicks on the 'Sign In' button, they are redirected to the Login page. | E8: NA | F8: Yes | G8: NA | H8: NA | I8: NA | J8: NA
A9: TC_Home_08 | B9: Home | C9: Post login | D9: Verify that upon successful login, the user is redirected to the Home page | E9: Yes | F9: Yes | G9: Yes | H9: Yes | I9: Yes | J9: Yes
A10: TC_Home_09 | B10: Home | C10: Post login | D10: Verify that the logged-in username is displayed on the top right of the screen after successful login | E10: NA | F10: Yes | G10: NA | H10: NA | I10: NA | J10: NA
D11: Verify that Profile and Sign Out options are present in the hamburger menu after successful login | E11: NA | F11: Yes | G11: NA | H11: NA | I11: NA | J11: NA
D12: Verify that upon successful login, the anonymous NMT service access capability is no longer available to the user | E12: NA | F12: Yes | G12: NA | H12: NA | I12: NA | J12: NA
A13: TC_Home_10 | B13: Home | C13: Post login | D13: Verify that the description on the ASR service card reads: "Convert spoken audio into accurate, readable text in Indic languages." | E13: NA | F13: Yes | G13: NA | H13: NA | I13: NA | J13: NA | N13: 46091 | O13: AI4IDS-774
A14: TC_Home_11 | B14: Home | C14: Post login | D14: Verify that the description on the TTS service card reads: "Generate natural-sounding speech from text in Indic languages." | E14: NA | F14: Yes | G14: NA | H14: NA | I14: NA | J14: NA | N14: 46091 | O14: AI4IDS-774
A15: TC_Home_12 | B15: Home | C15: Post login | D15: Verify that the description on the NMT service card reads: "Translate text instantly across Indic languages." | E15: NA | F15: Yes | G15: NA | H15: NA | I15: NA | J15: NA | N15: 46091 | O15: AI4IDS-774
A16: TC_Home_13 | B16: Home | C16: Post login | D16: Verify that the description on the LLM service card reads: 'Perform contextual translation and language tasks using advanced AI models.' | E16: NA | F16: Yes | G16: NA | H16: NA | I16: NA | J16: NA | N16: 46091 | O16: AI4IDS-774
A17: TC_Home_14 | B17: Home | C17: Post login | D17: Verify that the description on the Speech to Speech Pipeline service card reads: 'Transform spoken input into translated speech output using chained AI models.' | E17: NA | F17: Yes | G17: NA | H17: NA | I17: NA | J17: NA | N17: 46091 | O17: AI4IDS-774
A18: TC_Home_15 | B18: Home | C18: Post login | D18: Verify that the description on the OCR service card reads: 'Extract editable text from images and scanned documents.' | E18: NA | F18: Yes | G18: NA | H18: NA | I18: NA | J18: NA | N18: 46091 | O18: AI4IDS-774
A19: TC_Home_16 | B19: Home | C19: Post login | D19: Verify that the description on the Transliteration service card reads: 'Convert text from one script to another while preserving pronunciation.' | E19: NA | F19: Yes | G19: NA | H19: NA | I19: NA | J19: NA | N19: 46091 | O19: AI4IDS-774
A20: TC_Home_17 | B20: Home | C20: Post login | D20: Verify that the description on the Text Language Detection service card reads: 'Automatically identify the language and script of any text input.' | E20: NA | F20: Yes | G20: NA | H20: NA | I20: NA | J20: NA | N20: 46091 | O20: AI4IDS-774
A21: TC_Home_18 | B21: Home | C21: Post login | D21: Verify that the description on the Speaker Diarization service card reads: 'Separate audio into segments based on who is speaking.' | E21: NA | F21: Yes | G21: NA | H21: NA | I21: NA | J21: NA | N21: 46091 | O21: AI4IDS-774
A22: TC_Home_19 | B22: Home | C22: Post login | D22: Verify that the description on the Language Diarization service card reads: 'Detect language switches in real time within spoken audio.' | E22: NA | F22: Yes | G22: NA | H22: NA | I22: NA | J22: NA | N22: 46091 | O22: AI4IDS-774
A23: TC_Home_20 | B23: Home | C23: Post login | D23: Verify that the description on the Audio Language Detection service card reads: 'Identify the spoken language directly from an audio file.' | E23: NA | F23: Yes | G23: NA | H23: NA | I23: NA | J23: NA | N23: 46091 | O23: AI4IDS-774
A24: TC_Home_21 | B24: Home | C24: Post login | D24: Verify that the description on the NER service card reads: 'Extract key entities like names, locations, and organizations from text.' | E24: NA | F24: Yes | G24: NA | H24: NA | I24: NA | J24: NA | N24: 46091 | O24: AI4IDS-774
... A36: TC_Home_33 | B36: Home | C36: Post login | D36: Check the title on "NER" service page is, "Named Entity Recognition (NER)" | E36: NA | F36: Yes | G36: NA | H36: NA | I36: NA | J36: NA | N36: 46091 | O36: AI4IDS-712

Sheet Auth
A1: TC_ID | B1: Module | C1: Description | D1: Functionality | E1: Admin | F1: User | G1: Moderator | H1: Guest | I1: Adopter Admin | J1: Tenanat Admin | K1: UI Automation | L1: Backend | M1: Tags | N1: Created/Update on | O1: Ticket ID
A2: TC_Auth_01 | B2: Auth | C2: Sign in | D2: Accessibililty to the portal | E2: Yes | F2: Yes | G2: Yes | H2: Yes | N2: 46086
A3: TC_Auth_02 | B3: Auth | C3: Sign in | D3: Login with valid credentials | E3: Yes | F3: Yes | G3: Yes | H3: Yes | M3: Sanity | N3: 46086
A4: TC_Auth_03 | B4: Auth | C4: Sign in | D4: Login with invalid credentials should be restricted with appropriate error message.("Invalid credentials provided. Please log in again.") | E4: Yes | F4: Yes | G4: Yes | H4: Yes | M4: Sanity | N4: 46086
A5: TC_Auth_04 | B5: Auth | C5: Sign in | D5: Login with Oauth login(Google) | E5: Yes | F5: Yes | G5: Yes | H5: Yes | M5: Sanity | N5: 46086
A6: TC_Auth_05 | B6: Auth | C6: Sign in | D6: Verify user can see the password by clicking on the eye icon. | E6: Yes | N6: 46086
A7: TC_Auth_06 | B7: Auth | C7: Sign in | D7: Check the portal remains active for a day, when rember me is unchecked as user logs in. | E7: Yes | F7: Yes | G7: Yes | H7: Yes | N7: 46086
A8: TC_Auth_07 | B8: Auth | C8: Sign in | D8: Check the portal remains active for a 7 days, when rember me is checked as user logs in. | E8: Yes | F8: Yes | G8: Yes | H8: Yes | N8: 46086
A9: TC_Auth_08 | B9: Auth | C9: Sign up | D9: Check user cannot sign up with an existing email. And appropriate error message | E9: Yes | F9: Yes | G9: Yes | H9: Yes | M9: Sanity | N9: 46086
A10: TC_Auth_09 | B10: Auth | C10: Sign up | D10: Check email validation for email field. | E10: Yes | F10: Yes | G10: Yes | H10: Yes | N10: 46086
A11: TC_Auth_10 | B11: Auth | C11: Sign up | D11: Check Password and confirm password cannot be different. And corresponding error message. | E11: Yes | F11: Yes | G11: Yes | H11: Yes | N11: 46086
A12: TC_Auth_11 | B12: Auth | C12: Sign up | D12: Check user can sign up with an unique email. Appropriate success message. | E12: Yes | F12: Yes | G12: Yes | H12: Yes | M12: Sanity | N12: 46086
A13: TC_Auth_12 | B13: Auth | C13: Sign up | D13: Signed up user should be able to login with the provided credentials | E13: Yes | F13: Yes | G13: Yes | H13: Yes | M13: Sanity | N13: 46086
A14: TC_Auth_13 | B14: Auth | C14: Sign up | D14: All newly created users should be assigned with the Role "user" | E14: Yes | F14: Yes | G14: Yes | H14: Yes | M14: Sanity | N14: 46086
A15: TC_Auth_14 | B15: Auth | C15: Signout | D15: Verify user is logged in user is signed out of the portal by clicking on sign out | E15: Yes | F15: Yes | G15: Yes | H15: Yes

Sheet User Management
A1: TC_ID | B1: Module | C1: Description | D1: Functionality | E1: Admin | F1: User | G1: Moderator | H1: Guest | I1: Adopter Admin | J1: Tenanat Admin | K1: UI Automation | L1: Backend | M1: Tags | N1: Created/Update on | O1: Ticket ID
A2: TC_UserMang_01 | B2: User Management | C2: View | D2: Check user can access the profile page. | E2: Yes | F2: Yes | G2: Yes | H2: Yes
A3: TC_UserMang_02 | B3: User Management | C3: View | D3: Check user can view Full name, Username, Email, Phone number, Time zone, Status, Verified and Account created on, under user details. | E3: NA | F3: Yes | G3: NA | H3: NA | N3: 46091 | O3: AI4IDS-719
A4: TC_UserMang_03 | B4: User Management | C4: Edit | D4: User can edit and change the Full nanme | E4: NA | F4: Yes | G4: NA | H4: NA | M4: Sanity
A5: TC_UserMang_04 | B5: User Management | C5: Edit | D5: User can edit and change the Phone number | E5: NA | F5: Yes | G5: NA | H5: NA
A6: TC_UserMang_05 | B6: User Management | C6: Edit | D6: User can edit and change the Timezone | E6: NA | F6: Yes | G6: NA | H6: NA
A7: TC_UserMang_06 | B7: User Management | C7: Edit | D7: User should not be able to edit and change Username | E7: NA | F7: Yes | G7: NA | H7: NA | M7: Sanity
A8: TC_UserMang_07 | B8: User Management | C8: Edit | D8: User should not be able to edit and change email | E8: NA | F8: Yes | G8: NA | H8: NA | M8: Sanity
A9: TC_UserMang_08 | B9: User Management | C9: Edit | D9: User should not be able to edit and change Status | E9: NA | F9: Yes | G9: NA | H9: NA
A10: TC_UserMang_09 | B10: User Management | C10: Edit | D10: User should not be able to edit and change Verified field | E10: NA | F10: Yes | G10: NA | H10: NA
A11: TC_UserMang_10 | B11: User Management | C11: Edit | D11: User should be able to edit and change Account Created on. | E11: NA | F11: Yes | G11: NA | H11: NA | N11: 46091 | O11: AI4IDS-719
A12: TC_UserMang_11 | B12: User Management | C12: Edit | D12: Check place holder is present for all fields | E12: NA | F12: Yes | G12: NA | H12: NA | N12: 46091 | O12: AI4IDS-719
A13: TC_UserMang_12 | B13: User Management | C13: View | D13: While viewing, user should be able to see only the last four digits and country code in the phone number field | E13: NA | F13: Yes | G13: NA | H13: NA | N13: 46091 | O13: AI4IDS-719
A14: TC_UserMang_13 | B14: User Management | C14: Edit | D14: While editing user should be able to see the entire phone number field. | E14: NA | F14: Yes | G14: NA | H14: NA | N14: 46091 | O14: AI4IDS-719
A15: TC_UserMang_14 | B15: User Management | C15: View | D15: Check Account created on field is present and displays the date user was signed up or created | E15: NA | F15: Yes | G15: NA | H15: NA | N15: 46091 | O15: AI4IDS-719
A16: TC_UserMang_15 | B16: User Management | C16: View | D16: User view and edit should not have Language preference fields. | E16: NA | F16: Yes | G16: NA | H16: NA | N16: 46091 | O16: AI4IDS-719
B55: API Key Management | D55: Check filters in the page.
B58: API Key | D58: Select an API key from the list.
B59: API Key | D59: Choosen API key should remain selected, untill a different API key is selected.
B60: API Key | D60: VIew choosen API key
B61: API Key | D61: Copy API key
B76: Multi Tenancy | D76: Create a tenant
D77: View and update a tenant

Sheet Role Management
A1: TC_ID | B1: Module | C1: Description | D1: Functionality | E1: Admin | F1: User | G1: Moderator | H1: Guest | I1: Adopter Admin | J1: Tenanat Admin | K1: UI Automation | L1: Backend | M1: Tags | N1: Created/Update on | O1: Ticket ID
A2: TC_Role_01 | B2: Roles | C2: Role management | D2: Verify user can access the "Roles" section from profiles section. | E2: Yes | F2: No | G2: No | H2: No
A3: TC_Role_02 | B3: Roles | C3: Role management | D3: Check user can be slected to assign roles. | E3: Yes | F3: NA | G3: NA | H3: NA
A4: TC_Role_03 | B4: Roles | C4: Role management | D4: Check all available roles are listed on screen with description, by clicking on "Load Roles" (ADMIN, USER, GUEST, MODERATOR, TENANT ADMIN) | E4: Yes | F4: NA | G4: NA | H4: NA | N4: 46104 | O4: AI4IDS-719, AI4IDS-760
A5: TC_Role_04 | B5: Roles | C5: Role management | D5: When a user is selected current role should reflect on screen. | E5: Yes | F5: NA | G5: NA | H5: NA
A6: TC_Role_05 | B6: Roles | C6: Role management | D6: When a user is selected Select role drop down should appear on screen. | E6: Yes | F6: NA | G6: NA | H6: NA
A7: TC_Role_06 | B7: Roles | C7: Role management | D7: Verify confirmation pop up, with confirm and cancel button appears on screen. Claiming user's permissioins will be altered according to the new role. | E7: Yes | F7: NA | G7: NA | H7: NA | N7: 46091 | O7: AI4IDS-719
A8: TC_Role_07 | B8: Roles | C8: Role management | D8: Verify that clicking Cancel on confirmation pop up, dismisses the pop-up and the user's role remains unchanged | E8: Yes | F8: NA | G8: NA | H8: NA | N8: 46091 | O8: AI4IDS-719
A9: TC_Role_08 | B9: Roles | C9: Role management | D9: Verify that clicking Confirm on the confirmation pop up, updates the user's role successfully. With appropriate error message. | E9: Yes | F9: NA | G9: NA | H9: NA | M9: Sanity | N9: 46091 | O9: AI4IDS-719
A10: TC_Role_09 | B10: Roles | C10: Role management | D10: When a new role is added to an user, old role should get disengaged. | E10: Yes | F10: NA | G10: NA | H10: NA
A11: TC_Role_10 | B11: Roles | C11: Role management | D11: Verify the permissions of the newly assigned role is transfered accordingly, by logging in. | E11: Yes | F11: Yes | G11: Yes | H11: Yes | M11: Sanity
A12: TC_Role_11 | B12: Roles | C12: Role management | D12: A user can have only one role at any given instance. | E12: Yes | F12: NA | G12: NA | H12: NA
A13: TC_Role_12 | B13: Roles | C13: Role management | D13: In User drop down, user list should be in alphabetical order. | E13: Yes | F13: NA | G13: NA | H13: NA | N13: 46091 | O13: AI4IDS-719
A14: TC_Role_13 | B14: Roles | C14: Role management | D14: After selecting a user, clicking on the user drop down should still retain the alphabetical order. | E14: Yes | F14: NA | G14: NA | H14: NA | N14: 46091 | O14: AI4IDS-719
A15: TC_Role_14 | B15: Roles | C15: Role management | D15: Check placeholder in Select role drop down should be, "Select a role to assign to this user." | E15: Yes | F15: NA | G15: NA | H15: NA | N15: 46091 | O15: AI4IDS-719
A16: TC_Role_15 | B16: Roles | C16: Role management | D16: Check Select role drop down is not preselected with any role. | E16: Yes | F16: NA | G16: NA | H16: NA | N16: 46091 | O16: AI4IDS-719

Sheet API KEY Management
A1: TC_ID | B1: Module | C1: Description | D1: Functionality | E1: Admin | F1: User | G1: Moderator | H1: Guest | I1: Adopter Admin | J1: Tenanat Admin | K1: UI Automation | L1: Backend | M1: Tags | N1: Created/Update on | O1: Ticket ID
A2: TC_APIKEY_01 | B2: API KEY Management | C2: API KEY | D2: Verify that the user can access the API Key section from the Profile page | E2: Yes | F2: Yes | G2: Yes | H2: Yes | M2: Sanity
A3: TC_APIKEY_02 | B3: API KEY Management | C3: API KEY | D3: Verify that the user can access the Create API Key page from the Profile page | E3: Yes | F3: No | G3: No | H3: No | M3: Sanity
A4: TC_APIKEY_03 | B4: API KEY Management | C4: API KEY | D4: Verify that the user can access the API Key Management page from the Profile page | E4: Yes | F4: No | G4: No | H4: No | M4: Sanity
A5: TC_APIKEY_04 | B5: API KEY Management | C5: API KEY | D5: Verify that the API Key section lists API keys belonging to the logged-in user | E5: Yes | F5: NA | G5: Yes | H5: Yes
A6: TC_APIKEY_05 | B6: API KEY Management | C6: API KEY | D6: Check only active api keys are shown in the UI | E6: Yes | F6: Yes | G6: Yes | H6: Yes
A7: TC_APIKEY_06 | B7: API KEY Management | C7: API KEY | D7: User should be allowed ot choose a desired api key form the list, with appropriate success message. | E7: Yes | F7: Yes | G7: Yes | H7: Yes
A8: TC_APIKEY_07 | B8: API KEY Management | C8: API KEY | D8: Choosen API Key remains selected until user changes / unselects it. | E8: Yes | F8: Yes | G8: Yes | H8: Yes | M8: Sanity
A9: TC_APIKEY_08 | B9: API KEY Management | C9: API KEY | D9: Check if user can unslect an API key, with appropriate message on screen. And user can remain without an API key. | E9: Yes | F9: Yes | G9: Yes | H9: Yes
A10: TC_APIKEY_09 | B10: API KEY Management | C10: API KEY | D10: User can have only one API KEY selected at the moment | E10: Yes | F10: Yes | G10: Yes | H10: Yes | M10: Sanity
A11: TC_APIKEY_10 | B11: API KEY Management | C11: API KEY | D11: User should be able to see the choosen api key | E11: Yes | F11: Yes | G11: Yes | H11: Yes
A12: TC_APIKEY_11 | B12: API KEY Management | C12: API KEY | D12: User should be able to copy, without appropriate message on screen and paste only the choosen api key. | E12: Yes | F12: Yes | G12: Yes | H12: Yes
A13: TC_APIKEY_12 | B13: API KEY Management | C13: API KEY | D13: Check "Your API Key" is a non editable field. | E13: Yes
A14: TC_APIKEY_13 | B14: API KEY Management | C14: Create API KEY | D14: Ablitiy to choose a user to create an API KEY. | E14: Yes | F14: NA | G14: NA | H14: NA
A15: TC_APIKEY_14 | B15: API KEY Management | C15: Create API KEY | D15: Check load permissions, without choosing a user | E15: Yes | F15: NA | G15: NA | H15: NA
A16: TC_APIKEY_15 | B16: API KEY Management | C16: Create API KEY | D16: Check load permissions, after choosing an user. | E16: Yes | F16: NA | G16: NA | H16: NA
A17: TC_APIKEY_16 | B17: API KEY Management | C17: Create API KEY | D17: API KEY name is mandatory and user needs to provide a name. And appropriate error message. | E17: Yes | F17: NA | G17: NA | H17: NA
A18: TC_APIKEY_17 | B18: API KEY Management | C18: Create API KEY | D18: Expiry Days is manadatory and user cannot create a api key without expiry date.And appropriate error message | E18: Yes | F18: NA | G18: NA | H18: NA
A19: TC_APIKEY_18 | B19: API KEY Management | C19: Create API KEY | D19: Expiry of an API KEY cannot be more than 365 days | E19: Yes | F19: NA | G19: NA | H19: NA
A20: TC_APIKEY_19 | B20: API KEY Management | C20: Create API KEY | D20: Verify API KEY can be created with permissions to only few services | E20: Yes | F20: NA | G20: NA | H20: NA | M20: Sanity
A21: TC_APIKEY_20 | B21: API KEY Management | C21: Create API KEY | D21: Verify API KEY can be created with permissions to all the services | E21: Yes | F21: NA | G21: NA | H21: NA | M21: Sanity
A22: TC_APIKEY_21 | B22: API KEY Management | C22: Create API KEY | D22: Verify API KEY cannot be created without choosing atleast one service permission. | E22: Yes | F22: NA | G22: NA | H22: NA
A23: TC_APIKEY_22 | B23: API KEY Management | C23: API KEY Management | D23: Check API KEY can be filtered by user | E23: Yes | F23: NA | G23: NA | H23: NA
A24: TC_APIKEY_23 | B24: API KEY Management | C24: API KEY Management | D24: Check API KEY can be filtered by permission | E24: Yes | F24: NA | G24: NA | H24: NA
A25: TC_APIKEY_24 | B25: API KEY Management | C25: API KEY Management | D25: Check API KEY can be filtered by Status | E25: Yes | F25: NA | G25: NA | H25: NA
A26: TC_APIKEY_25 | B26: API KEY Management | C26: API KEY Management | D26: Check User, Permission, Status, Created, Expired and Action column has appropriate data. | E26: Yes | F26: NA | G26: NA | H26: NA
A27: TC_APIKEY_26 | B27: API KEY Management | C27: API KEY Management | D27: Check user can view API key details and check details in the API Details card.(View option from action column) | E27: Yes | F27: NA | G27: NA | H27: NA
A28: TC_APIKEY_27 | B28: API KEY Management | C28: API KEY Management | D28: API KEY can be updated | E28: Yes | F28: NA | G28: NA | H28: NA | M28: Sanity
A29: TC_APIKEY_28 | B29: API KEY Management | C29: API KEY Management | D29: Active API KEY can be made Inactive | E29: Yes | F29: NA | G29: NA | H29: NA
A30: TC_APIKEY_29 | B30: API KEY Management | C30: API KEY Management | D30: Inactive API KEY cannot be be made active | E30: Yes | F30: NA | G30: NA | H30: NA | N30: 46104 | O30: AI4IDS-927
A31: TC_APIKEY_30 | B31: API KEY Management | C31: API KEY Management | D31: Remove few existing permissions from an API KEY | E31: Yes | F31: NA | G31: NA | H31: NA
A32: TC_APIKEY_31 | B32: API KEY Management | C32: API KEY Management | D32: Add few more permission to the existing API KEY | E32: Yes | F32: NA | G32: NA | H32: NA
A33: TC_APIKEY_32 | B33: API KEY Management | C33: API KEY Management | D33: Add all permissions to an API KEY | E33: Yes | F33: NA | G33: NA | H33: NA
A34: TC_APIKEY_33 | B34: API KEY Management | C34: API KEY Management | D34: Each API KEY should have atleast one permission, so removing all the permissions should not allow to update. | E34: Yes | F34: NA | G34: NA | H34: NA | M34: Sanity

Sheet Model and Service Management
A1: TC_ID | B1: Module | C1: Description | D1: Functionality | E1: Admin | F1: User | G1: Moderator | H1: Guest | I1: Adopter Admin | J1: Tenanat Admin | K1: UI Automation | L1: Backend | M1: Tags | N1: Created/Update on | O1: Ticket ID | P1: Comments
A2: TC_Model_Service_01 | B2: Model and Service management. | C2: Model management | D2: Verify that the Model Registry tab under Model Management displays the list of available models. | E2: Yes | F2: No | G2: Yes | H2: No | M2: Sanity | N2: 46091 | O2: AI4IDS-774
A3: TC_Model_Service_02 | B3: Model and Service management. | C3: Model management | D3: Check Model Name, Model Version, Version Status, Task Type, Actions colums are present in model registry table. | E3: Yes | F3: NA | G3: Yes | H3: NA | N3: 46091 | O3: AI4IDS-774
A4: TC_Model_Service_03 | B4: Model and Service management. | C4: Model management | D4: Verify that clicking on a specific model in the Model Registry tab redirects the user to the View Model page of the respective model | E4: Yes | F4: NA | G4: Yes | H4: NA
A5: TC_Model_Service_04 | B5: Model and Service management. | C5: Model management | D5: Verify that clicking 'View' from the action column against a specific model in the Model Registry tab redirects the user to the View Model page of the respective model. | E5: Yes | F5: NA | G5: Yes | H5: NA
A6: TC_Model_Service_04 | B6: Model and Service management. | C6: Model management | D6: Verify that only models in ACTIVE state are available for selection during service creation | E6: Yes | F6: NA | G6: Yes | H6: NA | N6: 46106 | O6: AI4IDS-1112
A7: TC_Model_Service_05 | B7: Model and Service management. | C7: View model | D7: Verify that the View Model page displays only the following information: Model ID, Name, Description, Task Type, Status, License, Source, Domain, and Version. | E7: Yes | F7: NA | G7: Yes | H7: NA | N7: 46091 | O7: AI4IDS-774
A8: TC_Model_Service_06 | B8: Model and Service management. | C8: Model management | D8: Create a model (Applicable for all 11 services) | E8: Yes | F8: NA | G8: Yes | H8: NA | M8: Sanity
A9: TC_Model_Service_07 | B9: Model and Service management. | C9: Model management | D9: Naming convention of the model created. | E9: Yes | F9: NA | G9: Yes | H9: NA
A10: TC_Model_Service_08 | B10: Model and Service management. | C10: Model management | D10: Update a model (Applicable for all 11 services) | E10: Yes | F10: NA | G10: Yes | H10: NA
A11: TC_Model_Service_09 | B11: Model and Service management. | C11: Model management | D11: View model (Applicable for all 11 services) | E11: Yes | F11: NA | G11: Yes | H11: NA
A12: TC_Model_Service_10 | B12: Model and Service management. | C12: Model management | D12: Deprecate a model (Applicable for all 11 services) | E12: Yes | F12: NA | G12: Yes | H12: NA
A13: TC_Model_Service_10 | B13: Model and Service management. | C13: Create Model | D13: Verify that a newly created model is in ACTIVE state by default | E13: Yes | F13: NA | G13: Yes | H13: NA | N13: 46106 | O13: AI4IDS-1112
A14: TC_Model_Service_17 | B14: Model and Service management. | C14: Model registry filter | D14: Verify that the Model Registry supports text-based search and that models can be searched by model name | E14: Yes | F14: NA | G14: Yes | H14: NA
A15: TC_Model_Service_18 | B15: Model and Service management. | C15: Model registry filter | D15: Verify that the Model Registry supports text-based search and that models can be searched by Task type | E15: Yes | F15: NA | G15: Yes | H15: NA
A16: TC_Model_Service_19 | B16: Model and Service management. | C16: Model registry filter | D16: Verify that a "No results found" message is displayed when a model name search returns no matching results. | E16: Yes | F16: NA | G16: Yes | H16: NA
A17: TC_Model_Service_20 | B17: Model and Service management. | C17: Model registry filter | D17: Verify that the Model Registry can be filtered by Version Status and that the filtered results display correctly | E17: Yes | F17: NA | G17: Yes | H17: NA | N17: 46104 | O17: AI4IDS-781
A18: TC_Model_Service_21 | B18: Model and Service management. | C18: Model registry filter | D18: Verify that the Model Registry can be filtered by Task Type and that the filtered results display correctly. | E18: Yes | F18: NA | G18: Yes | H18: NA | N18: 46104 | O18: AI4IDS-781
A19: TC_Model_Service_22 | B19: Model and Service management. | C19: Model registry filter | D19: Verify that applying search text together with Version Status filter and Task Type filter returns results that match all three criteria simultaneously. | E19: Yes | F19: NA | G19: Yes | H19: NA | N19: 46104 | O19: AI4IDS-781
A20: TC_Model_Service_23 | B20: Model and Service management. | C20: Model registry filter | D20: Verify that applying search text together with the Version Status filter returns results that match both criteria. | E20: Yes | F20: NA | G20: Yes | H20: NA | N20: 46104 | O20: AI4IDS-781
A21: TC_Model_Service_24 | B21: Model and Service management. | C21: Model registry filter | D21: Verify that applying search text together with the Task Type filter returns results that match both criteria. | E21: Yes | F21: NA | G21: Yes | H21: NA | N21: 46104 | O21: AI4IDS-781
A22: TC_Model_Service_25 | B22: Model and Service management. | C22: Model registry filter | D22: Verify that applying the Version Status filter together with the Task Type filter returns results that match both criteria. | E22: Yes | F22: NA | G22: Yes | H22: NA | N22: 46104 | O22: AI4IDS-781
A23: TC_Model_Service_26 | B23: Model and Service management. | C23: Model registry filter | D23: Verify that the applied search text and selected filters are clearly visible on screen.(all 3) | E23: Yes | F23: NA | G23: Yes | H23: NA | N23: 46104 | O23: AI4IDS-781
A24: TC_Model_Service_27 | B24: Model and Service management. | C24: Model registry filter | D24: Verify that the search text can be cleared independently and that the results update correctly based on the remaining active filters. | E24: Yes | F24: NA | G24: Yes | H24: NA | N24: 46104 | O24: AI4IDS-781
A25: TC_Model_Service_28 | B25: Model and Service management. | C25: Model registry filter | D25: Verify that the Version Status filter can be cleared independently and that the results update correctly based on the remaining active filters. | E25: Yes | F25: NA | G25: Yes | H25: NA | N25: 46104 | O25: AI4IDS-781
A26: TC_Model_Service_29 | B26: Model and Service management. | C26: Model registry filter | D26: Verify that the Task Type filter can be cleared independently and that the results update correctly based on the remaining active filters. | E26: Yes | F26: NA | G26: Yes | H26: NA | N26: 46104 | O26: AI4IDS-781
A27: TC_Model_Service_30 | B27: Model and Service management. | C27: Model registry filter | D27: Verify that all search text and filters can be cleared simultaneously and that the full unfiltered results are restored. | E27: Yes | F27: NA | G27: Yes | H27: NA | N27: 46104 | O27: AI4IDS-781
A28: TC_Model_Service_31 | B28: Model and Service management. | C28: Model registry filter | D28: Verify that pagination is displayed correctly when no search text or filters are applied and results span multiple pages. | E28: Yes | F28: NA | G28: Yes | H28: NA | N28: 46104 | O28: AI4IDS-781
... A41: TC_Model_Service_44 | B41: Model and Service management. | C41: Model registry ordering | D41: Verify that the ordering is maintained after search and filter are applied together on the Model Registry list | E41: Yes | F41: NA | G41: Yes | H41: NA | N41: 46104 | O41: AI4IDS-782
A42: TC_Model_Service_45 | B42: Model and Service management. | C42: Model registry ordering | D42: Verify that models sharing the same created or updated timestamp are secondarily ordered alphabetically by model name | E42: Yes | F42: NA | G42: Yes | H42: NA | N42: 46104 | O42: AI4IDS-782 | P42: Review the case, it cannot happen likely
A43: TC_Model_Service_46 | B43: Model and Service management. | C43: Model deprecate | D43: Verify the confirmation popup appears when the user clicks Deprecate from the Action column of the Model Registry page. | E43: Yes | F43: NA | G43: Yes | H43: NA | N43: 46104 | O43: AI4IDS-741, AI4IDS-774
A44: TC_Model_Service_47 | B44: Model and Service management. | C44: Model deprecate | D44: Verify the popup displays the correct model name and it displays the message "Deprecated models cannot be used for new services." | E44: Yes | F44: NA | G44: Yes | H44: NA | N44: 46104 | O44: AI4IDS-741, AI4IDS-774
A45: TC_Model_Service_48 | B45: Model and Service management. | C45: Model deprecate | D45: Verify the model is deprecated successfully upon clicking Confirm and the model no longer appears as available to create a service. | E45: Yes | F45: NA | G45: Yes | H45: NA | M45: Sanity | N45: 46104 | O45: AI4IDS-741, AI4IDS-774, AI4IDS-1112
A46: TC_Model_Service_49 | B46: Model and Service management. | C46: Model deprecate | D46: Verify the model remains active upon clicking Cancel on the Deprecate confirmation popup. | E46: Yes | F46: NA | G46: Yes | H46: NA | N46: 46104 | O46: AI4IDS-741, AI4IDS-774
A47: TC_Model_Service_50 | B47: Model and Service management. | C47: Model deprecate | D47: Verify the Deprecate confirmation popup closes when clicking outside of the popup. | E47: Yes | F47: NA | G47: Yes | H47: NA | N47: 46104 | O47: AI4IDS-741, AI4IDS-774
A48: TC_Model_Service_50 | B48: Model and Service management. | C48: Model deprecate | D48: Verify that an Admin cannot DEPRECATE a model that has published services associated with it | E48: Yes | F48: NA | G48: Yes | H48: NA | N48: 46106 | O48: AI4IDS-1112
A49: TC_Model_Service_50 | B49: Model and Service management. | C49: Model deprecate | D49: Verify that a model is available to deprecate when all services associated with it are UNPUBLISHED | E49: Yes | F49: NA | G49: Yes | H49: NA | N49: 46106 | O49: AI4IDS-1112
A50: TC_Model_Service_51 | B50: Model and Service management. | C50: Model activate | D50: Verify the confirmation popup appears when the user clicks Activate from the Action column of the Model Registry page. | E50: Yes | F50: NA | G50: Yes | H50: NA | N50: 46104 | O50: AI4IDS-741, AI4IDS-774
A51: TC_Model_Service_52 | B51: Model and Service management. | C51: Model activate | D51: Verify the popup displays the correct model name and it displays the message "The model will be available for services again." | E51: Yes | F51: NA | G51: Yes | H51: NA | N51: 46104 | O51: AI4IDS-741, AI4IDS-774
A52: TC_Model_Service_53 | B52: Model and Service management. | C52: Model activate | D52: Verify the model is activated successfully upon clicking Confirm and the model is available for new services after activation. | E52: Yes | F52: NA | G52: Yes | H52: NA | M52: Sanity | N52: 46104 | O52: AI4IDS-741, AI4IDS-774, AI4IDS-1112
...

Sheet Multi Tenancy
A1: TC_ID | B1: Module | C1: Description | D1: Functionality | E1: Admin | F1: User | G1: Moderator | H1: Guest | I1: Adopter Admin | J1: Tenanat Admin | K1: UI Automation | L1: Backend | M1: Tags | N1: Created/Update on | O1: Ticket ID
A2: TC_MT_01 | B2: Multi Tenancy | C2: Multi tenant management | D2: Verify Adopter admin can access Multi Tenant Management page. And have an access to create new tenant. | E2: No | F2: No | G2: No | H2: No | I2: Yes | J2: No
A3: TC_MT_02 | B3: Multi Tenancy | C3: Create Tenant | D3: Verify that an authenticated adopter Admin can successfully create a tenant by providing all mandatory fields. | E3: NA | F3: NA | G3: NA | H3: NA | I3: Yes | J3: NA | M3: Sanity
A4: TC_MT_03 | B4: Multi Tenancy | C4: Create Tenant | D4: Verify that registration fails when attempting to create a tenant with an email that already exists in the system. | E4: NA | F4: NA | G4: NA | H4: NA | I4: Yes | J4: NA
A5: TC_MT_04 | B5: Multi Tenancy | C5: Create Tenant | D5: Verify that a tenant can be created with a subscription to one or more services offered by the adopter | E5: NA | F5: NA | G5: NA | H5: NA | I5: Yes | J5: NA
A6: TC_MT_05 | B6: Multi Tenancy | C6: Create Tenant | D6: Verify that a tenant can be created with subscriptions to all services offered by the adopter. | E6: NA | F6: NA | G6: NA | H6: NA | I6: Yes | J6: NA
A7: TC_MT_06 | B7: Multi Tenancy | C7: Create Tenant | D7: Verify that tenant creation fails when no service is selected, and an appropriate error message is displayed. | E7: NA | F7: NA | G7: NA | H7: NA | I7: Yes | J7: NA
A8: TC_MT_07 | B8: Multi Tenancy | C8: Create Tenant | D8: Verify that the list of available services shown during tenant creation contains only the services that the adopter has subscribed to, and does not include any services outside the adopter's catalog. | E8: NA | F8: NA | G8: NA | H8: NA | I8: Yes | J8: NA
A9: TC_MT_08 | B9: Multi Tenancy | C9: Create Tenant Email | D9: Verify that upon tenant creation, the verification email is automatically sent to the Tenant Admin without requiring any manual action from the Adopter Admin. | E9: NA | F9: NA | G9: NA | H9: NA | I9: Yes | J9: NA | M9: Sanity | N9: 46106 | O9: AI4IDS-761
A10: TC_MT_09 | B10: Multi Tenancy | C10: Create Tenant | D10: Verify that a newly created tenant has status PENDING before the email verification step is completed. | E10: NA | F10: NA | G10: NA | H10: NA | I10: Yes | J10: NA | N10: 46106 | O10: AI4IDS-1112
A11: TC_MT_10 | B11: Multi Tenancy | C11: Create Tenant | D11: Verify that the credentials generated upon tenant creation carry the TENANT_ADMIN role. | E11: NA | F11: NA | G11: NA | H11: NA | I11: Yes | J11: NA | O11: AI4IDS-656
A12: TC_MT_11 | B12: Multi Tenancy | C12: Create Tenant Email | D12: Verify that an Adopter Admin can send verification emails to a newly created Tenant Admin whose verification email sent during registration has expired, and that each resend attempt delivers a new verification email to the registered email address. | E12: NA | F12: NA | G12: NA | H12: NA | I12: Yes | J12: NA | N12: 46106 | O12: AI4IDS-761
A13: TC_MT_12 | B13: Multi Tenancy | C13: Create Tenant Email | D13: Verify that each resend attempt by an Adopter Admin returns an appropriate success message on screen. | E13: NA | F13: NA | G13: NA | H13: NA | I13: Yes | J13: NA | N13: 46106 | O13: AI4IDS-761
A14: TC_MT_13 | B14: Multi Tenancy | C14: Create Tenant Email | D14: Verify that the option to resend the verification email becomes available only after the initial or previous verification link has expired. | E14: NA | F14: NA | G14: NA | H14: NA | I14: Yes | J14: NA | N14: 46106 | O14: AI4IDS-761
A15: TC_MT_14 | B15: Multi Tenancy | C15: Create Tenant Email | D15: Verify that the system does not allow more than one active verification link to exist at the same time for a given Tenant Admin. | E15: NA | F15: NA | G15: NA | H15: NA | I15: Yes | J15: NA | N15: 46106 | O15: AI4IDS-761
A16: TC_MT_15 | B16: Multi Tenancy | C16: Create Tenant Email | D16: Verify that the verification email sent to the Tenant Admin contains the message: "To receive the verification email again, please coordinate with the Platform Admin, mention the Tenant ID, and request re-initiation of the email verification process." | E16: NA | F16: NA | G16: NA | H16: NA | I16: Yes | J16: NA | N16: 46106 | O16: AI4IDS-761
A17: TC_MT_16 | B17: Multi Tenancy | C17: Multi tenant management | D17: Verify that the Adopter Admin can configure the expiry duration of the verification email sent to a newly created Tenant Admin. | E17: NA | F17: NA | G17: NA | H17: NA | I17: Yes | J17: NA | N17: 46106 | O17: AI4IDS-761
A18: TC_MT_17 | B18: Multi Tenancy | C18: Create Tenant Email | D18: Verify that the verification email sent to a newly created Tenant Admin becomes invalid after the expiry duration configured by the Adopter Admin. | E18: NA | F18: NA | G18: NA | H18: NA | I18: Yes | J18: NA | N18: 46106 | O18: AI4IDS-761
A19: TC_MT_18 | B19: Multi Tenancy | C19: Create Tenant Email | D19: Verify that subsequent verification emails resent by the Adopter Admin also expire after the configured expiry duration. | E19: NA | F19: NA | G19: NA | H19: NA | I19: Yes | J19: NA | N19: 46106 | O19: AI4IDS-761
A20: TC_MT_14 | B20: Multi Tenancy | C20: Create Tenant | D20: Verify that only the most recently sent verification email successfully activates the Tenant Admin account. | E20: NA | F20: NA | G20: NA | H20: NA | I20: Yes | J20: NA
A21: TC_MT_15 | B21: Multi Tenancy | C21: Create Tenant | D21: Verify that all previously sent verification emails are invalidated upon resend, and attempting to use them returns an appropriate error message. | E21: NA | F21: NA | G21: NA | H21: NA | I21: Yes | J21: NA
A22: TC_MT_16 | B22: Multi Tenancy | C22: Create Tenant | D22: Verify that a verification email link becomes invalid after 15 minutes from the time it was sent. | E22: NA | F22: NA | G22: NA | H22: NA | I22: Yes | J22: NA
A23: TC_MT_17 | B23: Multi Tenancy | C23: Create Tenant | D23: Verify that attempting to use an expired verification email link displays an appropriate expiry message on the screen. | E23: NA | F23: NA | G23: NA | H23: NA | I23: Yes | J23: NA
A24: TC_MT_18 | B24: Multi Tenancy | C24: Create Tenant | D24: Verify that the tenant status is updated to ACTIVE once the Tenant Admin successfully verifies their email. | E24: NA | F24: NA | G24: NA | H24: NA | I24: Yes | J24: NA | M24: Sanity | N24: 46106 | O24: AI4IDS-1112
A25: TC_MT_19 | B25: Multi Tenancy | C25: Create Tenant | D25: Verify that attempting to send a verification email to an already active Tenant Admin returns an appropriate error message. | E25: NA | F25: NA | G25: NA | H25: NA | I25: Yes | J25: NA
A26: TC_MT_20 | B26: Multi Tenancy | C26: Create Tenant | D26: Verify that once the email is verified, the newly activated Tenant Admin receives an email containing their login password. | E26: NA | F26: NA | G26: NA | H26: NA | I26: Yes | J26: NA
A27: TC_MT_21 | B27: Multi Tenancy | C27: Create Tenant | D27: Verify that the newly activated Tenant Admin can successfully log in using the password received in the email, until the password is changed by the user. | E27: NA | F27: NA | G27: NA | H27: NA | I27: Yes | J27: NA
A28: TC_MT_22 | B28: Multi Tenancy | C28: View Tenant | D28: Verify that the Multi Tenant Management page displays all the tenants that exist in the system. | E28: NA | F28: NA | G28: NA | H28: NA | I28: Yes | J28: NA
A29: TC_MT_23 | B29: Multi Tenancy | C29: View Tenant | D29: Verify that clicking on a tenant in the Multi Tenant Management page navigates the user to the respective tenant's view page. | E29: NA | F29: NA | G29: NA | H29: NA | I29: Yes | J29: NA
A30: TC_MT_24 | B30: Multi Tenancy | C30: View Tenant | D30: Verify that clicking the View button from the Action column in the Multi Tenant Management page navigates the user to the respective tenant's view page. | E30: NA | F30: NA | G30: NA | H30: NA | I30: Yes | J30: NA
A31: TC_MT_25 | B31: Multi Tenancy | C31: View Tenant | D31: Verify that the tenant view page displays all the relevant tenant details including Organization Name, Tenant ID, Contact Email, Domain, Created Date, Last Updated Date, and all subscribed services with their respective status (ENABLED/DISABLED) under the Services Summary section. | E31: NA | F31: NA | G31: NA | H31: NA | I31: Yes | J31: NA
A32: TC_MT_26 | B32: Multi Tenancy | C32: View Tenant | D32: Verify that the tenant view page displays the correct tenant status(ACTIVE/SUSPENDED/INACTIVE) | E32: NA | F32: NA | G32: NA | H32: NA | I32: Yes | J32: NA
A33: TC_MT_27 | B33: Multi Tenancy | C33: View Tenant | D33: Verify that clicking on the Users tab in the tenant view page displays all the users associated with that tenant. | E33: NA | F33: NA | G33: NA | H33: NA | I33: Yes | J33: NA
A34: TC_MT_28 | B34: Multi Tenancy | C34: Suspend Tenant | D34: Verify that clicking the suspend action displays a confirmation dialog showing the tenant ID, the action to be performed, and the current status before proceeding. | E34: NA | F34: NA | G34: NA | H34: NA | I34: Yes | J34: NA | O34: AI4IDS-741
A35: TC_MT_29 | B35: Multi Tenancy | C35: Suspend Tenant | D35: Verify that clicking Cancel on the suspend confirmation dialog dismisses the dialog and leaves the tenant status unchanged. | E35: NA | F35: NA | G35: NA | H35: NA | I35: Yes | J35: NA | O35: AI4IDS-741
A36: TC_MT_30 | B36: Multi Tenancy | C36: Suspend Tenant | D36: Verify that an Adopter Admin can successfully suspend an Active tenant by clicking Confirm in the confirmation dialog. | E36: NA | F36: NA | G36: NA | H36: NA | I36: Yes | J36: NA | O36: AI4IDS-741
A37: TC_MT_31 | B37: Multi Tenancy | C37: Suspend Tenant | D37: Verify that a tenant's status is updated to SUSPENDED after the Adopter Admin confirms the suspend action in the confirmation dialog. | E37: NA | F37: NA | G37: NA | H37: NA | I37: Yes | J37: NA | M37: Sanity | O37: AI4IDS-741, AI4IDS-1112
A38: TC_MT_32 | B38: Multi Tenancy | C38: Suspended Tenant - login | D38: Verify that a Tenant Admin belonging to a SUSPENDED tenant cannot log in to the system and receives an appropriate error message. | E38: NA | F38: NA | G38: NA | H38: NA | I38: Yes | J38: NA | M38: Sanity
A39: TC_MT_33 | B39: Multi Tenancy | C39: Suspended Tenant - edit | D39: Verify that a suspended tenant cannot be edited and an appropriate error message is displayed. | E39: NA | F39: NA | G39: NA | H39: NA | I39: Yes | J39: NA
A40: TC_MT_34 | B40: Multi Tenancy | C40: Suspended Tenant - user actions | D40: Verify that a new user cannot be created under a suspended tenant. | E40: NA | F40: NA | G40: NA | H40: NA | I40: Yes | J40: NA
...

Sheet Backlog
A1: TC to be revamped | B1: Module | C1: Status | D1: Comments | L1: Access/Role | M1: Anonymous user | N1: Guest | O1: User | P1: Moderator | Q1: Admin | R1: Tenant Admin
A2: https://coss-team-ai4x.atlassian.net/browse/AI4IDS-767 | C2: Done | L2: Login | M2: NA | N2: Yes | O2: Yes | P2: Yes | Q2: Yes | R2: Yes
A3: https://coss-team-ai4x.atlassian.net/browse/AI4IDS-769 | C3: Done | L3: Profile | M3: NA | N3: Yes | O3: Yes | P3: Yes | Q3: Yes | R3: Yes
A4: https://coss-team-ai4x.atlassian.net/browse/AI4IDS-771 | C4: Done | L4: Test Model types and Models (includes pipeline) | M4: Yes (configurable) Default: NMT(5 translations per hour) | N4: Yes (configurable) Default: NMT, ASR, TTS | O4: Yes | P4: Yes | Q4: Yes | R4: Yes
A5: https://coss-team-ai4x.atlassian.net/browse/AI4IDS-773 | C5: Done | L5: View Model Registry | M5: No | N5: No | O5: No | P5: Yes | Q5: Yes | R5: Yes
A6: https://coss-team-ai4x.atlassian.net/browse/AI4IDS-927 | C6: Done | D6: No case needed and the entire Auth service is re written. | L6: Create, Publish/unpublish, Delete Models/Services | M6: No | N6: No | O6: No | P6: Yes | Q6: Yes | R6: No
A7: https://coss-team-ai4x.atlassian.net/browse/AI4IDS-753 | C7: On Hold | D7: Usual functionalities are working, but LLM service is unavailable. | L7: Assign Role/s | M7: NA | N7: No | O7: No | P7: No | Q7: Yes | R7: Yes
A8: https://coss-team-ai4x.atlassian.net/browse/AI4IDS-760 | C8: Done | D8: Modified a case in Role management | L8: API Key creation | M8: No | N8: No | O8: No | P8: No | Q8: Yes | R8: Yes
A9: https://coss-team-ai4x.atlassian.net/browse/AI4IDS-741 | C9: Partially Done | D9: Task 8 : Service publish/unpublish/Delete, Model deprecate / activate. - Coverage Pending at Multi tenant, role and api key management Task 7 / Task 9: SERVICES - For 12 services Task 10 - SERVICES - Requested 7 services | L9: Logs | M9: No | N9: No | O9: Yes | P9: Yes | Q9: Yes | R9: Yes
A10: https://coss-team-ai4x.atlassian.net/browse/AI4IDS-777 | C10: Done | D10: except LLM everything is covered. | L10: Tenant Management | M10: No | N10: No | O10: No | P10: No | Q10: Yes | R10: Yes
A11: https://coss-team-ai4x.atlassian.net/browse/AI4IDS-886 | C11: Done
A12: https://coss-team-ai4x.atlassian.net/browse/AI4IDS-881 | B12: Model and Service Management | C12: Done
A13: https://coss-team-ai4x.atlassian.net/browse/AI4IDS-781 | C13: Done
A14: https://coss-team-ai4x.atlassian.net/browse/AI4IDS-782 | B14: Model and Service Management | C14: Done
A15: https://coss-team-ai4x.atlassian.net/browse/AI4IDS-785 | B15: Model and Service Management | C15: Done
A16: https://coss-team-ai4x.atlassian.net/browse/AI4IDS-786 | B16: Model and Service Management | C16: Done
A17: https://coss-team-ai4x.atlassian.net/browse/AI4IDS-656 | C17: NA | D17: This is very generic ticket on tenant admin
A18: https://coss-team-ai4x.atlassian.net/browse/AI4IDS-579 | C18: NA | D18: This is very generic ticket on tenant status
A19: https://coss-team-ai4x.atlassian.net/browse/AI4IDS-514 | C19: Oh Hold | D19: This is on A/B testing API implementation
A20: https://coss-team-ai4x.atlassian.net/browse/AI4IDS-477 | C20: NA | D20: A ticket on, few parameter inclusion in register API
A21: https://coss-team-ai4x.atlassian.net/browse/AI4IDS-761 | B21: Multi Tenancy | C21: Done | D21: Tenant email registration.
A22: https://coss-team-ai4x.atlassian.net/browse/AI4IDS-1095 | C22: NA | D22: This is a temporary change.
A23: https://coss-team-ai4x.atlassian.net/browse/AI4IDS-1112 | B23: Multi Tenancy | C23: Partially Done | D23: Tenant_Transistion Tenant_User_Transition Model_Management Service_Management ARCHIVE service is not implemented

Sheet Services
A1: TC_ID | B1: Module | C1: Description | D1: Functionality | E1: Admin | F1: User | G1: Moderator | H1: Guest | I1: Adopter Admin | J1: Tenanat Admin | K1: UI Automation | L1: Backend | M1: Tags | N1: Created/Update on | O1: Ticket ID
A2: TC_Services_1 | B2: Services | C2: Valid API Key | D2: Access ASR service, with valid api key | E2: Yes | F2: Yes | G2: Yes | H2: Yes | I2: Yes | J2: Yes | M2: Sanity | N2: 46096
A3: TC_Services_2 | B3: Services | C3: Valid API Key | D3: Access NMT service, with valid api key | E3: Yes | F3: Yes | G3: Yes | H3: Yes | I3: Yes | J3: Yes | M3: Sanity | N3: 46096
A4: TC_Services_3 | B4: Services | C4: Valid API Key | D4: Access TTS service, with valid api key | E4: Yes | F4: Yes | G4: Yes | H4: Yes | I4: Yes | J4: Yes | M4: Sanity | N4: 46096
A5: TC_Services_4 | B5: Services | C5: Valid API Key | D5: Access Transliteration service, with valid api key | E5: Yes | F5: Yes | G5: Yes | H5: Yes | I5: Yes | J5: Yes | M5: Sanity | N5: 46096
A6: TC_Services_5 | B6: Services | C6: Valid API Key | D6: Access Audio language detection service, with valid api key | E6: Yes | F6: Yes | G6: Yes | H6: Yes | I6: Yes | J6: Yes | M6: Sanity | N6: 46096
A7: TC_Services_6 | B7: Services | C7: Valid API Key | D7: Access Text language detection service, with valid api key | E7: Yes | F7: Yes | G7: Yes | H7: Yes | I7: Yes | J7: Yes | M7: Sanity | N7: 46096
A8: TC_Services_7 | B8: Services | C8: Valid API Key | D8: Access Speaker diarization service, with valid api key | E8: Yes | F8: Yes | G8: Yes | H8: Yes | I8: Yes | J8: Yes | M8: Sanity | N8: 46096
A9: TC_Services_8 | B9: Services | C9: Valid API Key | D9: Access Language diarization service, with valid api key | E9: Yes | F9: Yes | G9: Yes | H9: Yes | I9: Yes | J9: Yes | M9: Sanity | N9: 46096
A10: TC_Services_9 | B10: Services | C10: Valid API Key | D10: Access OCR service, with valid api key | E10: Yes | F10: Yes | G10: Yes | H10: Yes | I10: Yes | J10: Yes | M10: Sanity | N10: 46096
A11: TC_Services_10 | B11: Services | C11: Valid API Key | D11: Access LLM service, with valid api key | E11: Yes | F11: Yes | G11: Yes | H11: Yes | I11: Yes | J11: Yes | M11: Sanity | N11: 46096
A12: TC_Services_11 | B12: Services | C12: Valid API Key | D12: Access NER service, with valid api key | E12: Yes | F12: Yes | G12: Yes | H12: Yes | I12: Yes | J12: Yes | M12: Sanity | N12: 46096
A13: TC_Services_12 | B13: Services | C13: Invalid API Key | D13: Verify that the user cannot access ASR service with an invalid API key | E13: Yes | F13: Yes | G13: Yes | H13: Yes | I13: Yes | J13: Yes | M13: Sanity | N13: 46096
... A15: TC_Services_14 | B15: Services | C15: Invalid API Key | D15: Verify that the user cannot access TTS service with an invalid API key | E15: Yes | F15: Yes | G15: Yes | H15: Yes | I15: Yes | J15: Yes | M15: Sanity | N15: 46096
A16: TC_Services_15 | B16: Services | C16: Invalid API Key | D16: Verify that the user cannot access Transliteration service with an invalid API key | E16: NA | F16: Yes | G16: NA | H16: NA | I16: NA | J16: NA | N16: 46096
A17: TC_Services_16 | B17: Services | C17: Invalid API Key | D17: Verify that the user cannot access Audio Language Detection service with an invalid API key | E17: NA | F17: Yes | G17: NA | H17: NA | I17: NA | J17: NA | N17: 46096
A18: TC_Services_17 | B18: Services | C18: Invalid API Key | D18: Verify that the user cannot access Text Language Detection service with an invalid API key | E18: NA | F18: Yes | G18: NA | H18: NA | I18: NA | J18: NA | N18: 46096
A19: TC_Services_18 | B19: Services | C19: Invalid API Key | D19: Verify that the user cannot access Speaker Diarization service with an invalid API key | E19: NA | F19: Yes | G19: NA | H19: NA | I19: NA | J19: NA | N19: 46096
A20: TC_Services_19 | B20: Services | C20: Invalid API Key | D20: Verify that the user cannot access Language Diarization service with an invalid API key | E20: NA | F20: Yes | G20: NA | H20: NA | I20: NA | J20: NA | N20: 46096
A21: TC_Services_20 | B21: Services | C21: Invalid API Key | D21: Verify that the user cannot access OCR service with an invalid API key | E21: NA | F21: Yes | G21: NA | H21: NA | I21: NA | J21: NA | N21: 46096
A22: TC_Services_21 | B22: Services | C22: Invalid API Key | D22: Verify that the user cannot access LLM service with an invalid API key | E22: NA | F22: Yes | G22: NA | H22: NA | I22: NA | J22: NA | N22: 46096
A23: TC_Services_22 | B23: Services | C23: Invalid API Key | D23: Verify that the user cannot access NER service with an invalid API key | E23: NA | F23: Yes | G23: NA | H23: NA | I23: NA | J23: NA | N23: 46096
A24: TC_Services_23 | B24: Services | C24: No API Key | D24: Verify that the user cannot access ASR service without an API key | E24: Yes | F24: Yes | G24: Yes | H24: Yes | I24: Yes | J24: Yes | M24: Sanity | N24: 46096
A25: TC_Services_24 | B25: Services | C25: No API Key | D25: Verify that the user cannot access NMT service without an API key | E25: Yes | F25: Yes | G25: Yes | H25: Yes | I25: Yes | J25: Yes | M25: Sanity | N25: 46096
A26: TC_Services_25 | B26: Services | C26: No API Key | D26: Verify that the user cannot access TTS service without an API key | E26: Yes | F26: Yes | G26: Yes | H26: Yes | I26: Yes | J26: Yes | M26: Sanity | N26: 46096
A27: TC_Services_26 | B27: Services | C27: No API Key | D27: Verify that the user cannot access Transliteration service without an API key | E27: NA | F27: Yes | G27: NA | H27: NA | I27: NA | J27: NA | N27: 46096
A28: TC_Services_27 | B28: Services | C28: No API Key | D28: Verify that the user cannot access Audio Language Detection service without an API key | E28: NA | F28: Yes | G28: NA | H28: NA | I28: NA | J28: NA | N28: 46096
